Workbook
Name CodLavorazioni: RiepilogoCostiOrari[#Headers]
Name CodLinea: RiepilogoCostiOrari[[#Headers],[L1]:[L3]]
Name CodLotto: Lotti[CodLotti]
Name CodProtezione: Protezioni[Tipo Operazione]
Name CodQuarter: #REF!
Name CodVariabili: #REF!
Name CodVeloCatena: VeloCatena[NomeFam]
Name CostoOraVern: CostiOraLavorazioni!$A$1:$D$4
Name FamiglieVeloc: VeloCatena[#All]
Name NrPreventivi: RigheOfferte[Nprev]
Name Paramentri: Parametri!$1:$1048576
Name Parametri: Tabella1[]
Name prezzi: 'riepilogo prezzi'!$1:$1048576
Name QuCostiLav: RiepilogoCostiOrari[NomeRisorsa]
Name Resa: Spessore!$B$4
Name RisorseVern: CostiVerniciatura[]
Name spessore: ReseMQ[]

Sheet RisorsaVerniciatura
A1: Risorsa | B1: TipoCosto | C1: UnMisura | D1: Qta | E1: PeriodoQ1-26 | F1: TotPerQ1-26 | G1: PeriodoQ2-26 | H1: TotPerQ2-26 | I1: PeriodoQ3-26 | J1: TotPerQ3-26 | L1: Etichette di riga | M1: Somma di TotPerQ1-26 | N1: Somma di TotPerQ2-26 | O1: Somma di TotPerQ3-26
A2: L1 | B2: Energia Elettrica | C2: Kwh | D2: 95 | E2: 0.31 | F2: =D2*E2 -> 29.45 | G2: 0.31 | H2: =D2*G2 -> 29.45 | I2: 0.31 | J2: =D2*I2 -> 29.45 | L2: L1 | M2: 690.7 | N2: 690.7 | O2: 690.7
A3: L1 | B3: Gas Metano | C3: Smc | D3: 85 | E3: 0.85 | F3: =D3*E3 -> 72.25 | G3: 0.85 | H3: =D3*G3 -> 72.25 | I3: 0.85 | J3: =D3*I3 -> 72.25 | L3: L2 | M3: 358.8 | N3: 358.8 | O3: 358.8
A4: L1 | B4: Manodopera | C4: nr | D4: 13 | E4: 27 | F4: =D4*E4 -> 351 | G4: 27 | H4: =D4*G4 -> 351 | I4: 27 | J4: =D4*I4 -> 351 | L4: L3 | M4: 459.4 | N4: 459.4 | O4: 459.4
A5: L1 | B5: Ammortamento | C5: nr | D5: 1 | E5: 100 | F5: =D5*E5 -> 100 | G5: 100 | H5: =D5*G5 -> 100 | I5: 100 | J5: =D5*I5 -> 100 | L5: Totale complessivo | M5: 1508.9 | N5: 1508.9 | O5: 1508.9
A6: L1 | B6: Affitto | C6: nr | D6: 1 | E6: 75 | F6: =D6*E6 -> 75 | G6: 75 | H6: =D6*G6 -> 75 | I6: 75 | J6: =D6*I6 -> 75
A7: L1 | B7: Spese Gestione Impianto | C7: nr | D7: 1 | E7: 28 | F7: =D7*E7 -> 28 | G7: 28 | H7: =D7*G7 -> 28 | I7: 28 | J7: =D7*I7 -> 28
A8: L1 | B8: Manutenzione | C8: nr | D8: 1 | E8: 35 | F8: =D8*E8 -> 35 | G8: 35 | H8: =D8*G8 -> 35 | I8: 35 | J8: =D8*I8 -> 35
A9: L2 | B9: Energia Elettrica | C9: Kwh | D9: 55 | E9: 0.31 | F9: =D9*E9 -> 17.05 | G9: 0.31 | H9: =D9*G9 -> 17.05 | I9: 0.31 | J9: =D9*I9 -> 17.05
A10: L2 | B10: Gas Metano | C10: Smc | D10: 55 | E10: 0.85 | F10: =D10*E10 -> 46.75 | G10: 0.85 | H10: =D10*G10 -> 46.75 | I10: 0.85 | J10: =D10*I10 -> 46.75
A11: L2 | B11: Manodopera | C11: nr | D11: 5 | E11: 27 | F11: =D11*E11 -> 135 | G11: 27 | H11: =D11*G11 -> 135 | I11: 27 | J11: =D11*I11 -> 135
A12: L2 | B12: Ammortamento | C12: nr | D12: 1 | E12: 55 | F12: =D12*E12 -> 55 | G12: 55 | H12: =D12*G12 -> 55 | I12: 55 | J12: =D12*I12 -> 55
A13: L2 | B13: Affitto | C13: nr | D13: 1 | E13: 55 | F13: =D13*E13 -> 55 | G13: 55 | H13: =D13*G13 -> 55 | I13: 55 | J13: =D13*I13 -> 55
A14: L2 | B14: Spese Gestione Impianto | C14: nr | D14: 1 | E14: 15 | F14: =D14*E14 -> 15 | G14: 15 | H14: =D14*G14 -> 15 | I14: 15 | J14: =D14*I14 -> 15
A15: L2 | B15: Manutenzione | C15: nr | D15: 1 | E15: 35 | F15: =D15*E15 -> 35 | G15: 35 | H15: =D15*G15 -> 35 | I15: 35 | J15: =D15*I15 -> 35
A16: L3 | B16: Energia Elettrica | C16: Kwh | D16: 65 | E16: 0.31 | F16: =D16*E16 -> 20.15 | G16: 0.31 | H16: =D16*G16 -> 20.15 | I16: 0.31 | J16: =D16*I16 -> 20.15
A17: L3 | B17: Gas Metano | C17: Smc | D17: 65 | E17: 0.85 | F17: =D17*E17 -> 55.25 | G17: 0.85 | H17: =D17*G17 -> 55.25 | I17: 0.85 | J17: =D17*I17 -> 55.25
... A22: L3 | B22: Manutenzione | C22: nr | D22: 1 | E22: 35 | F22: =D22*E22 -> 35 | G22: 35 | H22: =D22*G22 -> 35 | I22: 35 | J22: =D22*I22 -> 35

Sheet Spessore
A1: Parametri Polvere | B1: Valori
A2: Spessore medio | B2: 85
A3: Resa in Mq | B3: 7.3529412
A4: Kg/mq | B4: 0.1564

Sheet CostiOraLavorazioni
A1: NomeRisorsa | B1: L1 | C1: L2 | D1: L3 | E1: MON | F1: SAB | G1: SER | H1: PREP | I1: IMB | J1: SCHI | K1: Camp | L1: VTPX | M1: TRAS
A2: 202601 | B2: 690.7 | C2: 358.8 | D2: 459.4 | E2: 30 | F2: 60 | G2: 60 | H2: 30 | I2: 30 | J2: 60 | K2: 100 | L2: 793 | M2: 30
A3: 202602 | B3: 690.7 | C3: 358.8 | D3: 459.4 | E3: 30 | F3: 60 | G3: 60 | H3: 30 | I3: 30 | J3: 60 | K3: 100 | L3: 655 | M3: 30
A4: 202603 | B4: 690.7 | C4: 358.8 | D4: 459.4 | E4: 30 | F4: 60 | G4: 60 | H4: 30 | I4: 30 | J4: 65 | K4: 110 | L4: 687 | M4: 30

Sheet DescLavorazioni
A1: CodLav | B1: DescLav
A2: L1 | B2: Verniciatura
A3: L2 | B3: Verniciatura
A4: L3 | B4: Verniciatura
A5: MON | B5: Montaggio
A6: SAB | B6: Sabbiatura
A7: SER | B7: Serigrafia
A8: PREP | B8: Preparazione
A9: IMB | B9: Imballo
A10: SCHI | B10: Schiumatura
A11: CAMP | B11: Campionatura
A12: TRAS | B12: Trasporto
A13: VTPX | B13: Verniciatura extra Quality

Sheet Ricarichi
A1: Descrizione | B1: L1 | C1: L2 | D1: L3 | E1: MON | F1: SAB | G1: SER | H1: PREP | I1: IMB | J1: SCHI | K1: Camp | L1: TRAS | M1: VTPX
A2: 202301 | B2: 0.38 | C2: 0.38 | D2: 0.38 | E2: 0.38 | F2: 0.38 | G2: 0.4 | H2: 0.38 | I2: 0.38 | J2: 0.45 | K2: 0.35 | L2: 0.4 | M2: 0.45
A3: 202302 | B3: 0.38 | C3: 0.38 | D3: 0.25 | E3: 0.38 | F3: 0.38 | G3: 0.4 | H3: 0.38 | I3: 0.38 | J3: 0.45 | K3: 0.35 | L3: 0.4 | M3: 0.45
A4: 202303 | B4: 0.38 | C4: 0.38 | D4: 0.25 | E4: 0.38 | F4: 0.38 | G4: 0.4 | H4: 0.38 | I4: 0.38 | J4: 0.45 | K4: 0.38 | L4: 0.4 | M4: 0.45

Sheet Velocità
A1: NomeFam | B1: DescFam | C1: Velocita
A2: F0 | B2: lamiere F0 | C2: 0.25
A3: F1 | B3: lamiere F1 | C3: 1
A4: F2 | B4: lamiere F2 | C4: 1.5
A5: F3 | B5: lamiere F3 | C5: 2
A6: F4 | B6: lamiere F4 | C6: 2.5

Sheet Protezioni
A1: Tipo Operazione | B1: costo protezione
A2: Perno | B2: 0.18
A3: Filetto | B3: 0.18
A4: Foro | B4: 0.15
A5: Fastom | B5: 0.15
A6: A disegno | B6: 1
A7: Perno + R | B7: 0.3
A8: Filetto + R | B8: 0.3
A9: Foro + R | B9: 0.25
A10: Fastom + R | B10: 0.25
A11: A disegno + R | B11: 1.8

Sheet Lotti
A1: CodLotti | B1: QuotaFissa
A2: 0-50 | B2: 80
A3: 51-100 | B3: 65
A4: 101-500 | B4: 50
A5: 501-1000 | B5: 40
A6: 1001-oltre | B6: 30
A7: ZERO | B7: 10
A8: CAMP | B8: 80

Sheet Parametri
A1: Nr.Preventivo | B1: Numero Riga | C1: Cliente | D1: sub_cliente | E1: cod.Art. | F1: Descrizione | G1: q.ta offerta | H1: LINEA | I1: Colore | J1: Velocità | K1: superificie | L1: passo | M1: nr.pezzi Telaio | N1: nr.pezzi ora-unita | O1: KgPezzo | P1: Previsione Consumi Kg | Q1: Qta protez | R1: Tipo protezione
A2: =RigheOfferte[[#This Row],[Nprev]] -> 202601 | B2: =RigheOfferte[[#This Row],[Nriga]] -> 1 | C2: =RigheOfferte[[#This Row],[Cliente]] -> VERONA LAMIERE | D2: =RigheOfferte[[#This Row],[sub_cliente]] -> FRANKE | E2: =RigheOfferte[[#This Row],[cod.Art.]] -> 5600755201 | F2: =RigheOfferte[[#This Row],[Descrizione]] -> Mounting bracket valve group thermoblock | G2: =RigheOfferte[[#This Row],[Q.ta'']] -> 1000 | H2: =RigheOfferte[[#This Row],[Lavorazione]] -> L1 | I2: =RigheOfferte[[#This Row],[Colore]] -> P90005XLOP | J2: =RigheOfferte[[#This Row],[Velocità]] -> 2 | K2: =RigheOfferte[[#This Row],[Superf.pz Mq]] -> 0.057 | L2: =RigheOfferte[[#This Row],[passo]] -> 0.8 | M2: =RigheOfferte[[#This Row],[nr.pezzi Telaio]] -> 16 | N2: =RigheOfferte[[#This Row],[nr.pezzi ora-unita]] -> 2400 | O2: =Tabella1[[#This Row],[superificie]]*Resa -> 0.0089148 | P2: =Tabella1[[#This Row],[KgPezzo]]*Tabella1[[#This Row],[q.ta offerta]] -> 8.9148 | Q2: =RigheOfferte[[#This Row],[QtaProtez]] -> 0 | R2: =RigheOfferte[[#This Row],[Tipo Protezione]] -> 0
A3: =RigheOfferte[[#This Row],[Nprev]] -> 202602 | B3: =RigheOfferte[[#This Row],[Nriga]] -> 1 | C3: =RigheOfferte[[#This Row],[Cliente]] -> IMMERGAS | D3: =RigheOfferte[[#This Row],[sub_cliente]] -> IMMERGAS | E3: =RigheOfferte[[#This Row],[cod.Art.]] -> 3037280 | F3: =RigheOfferte[[#This Row],[Descrizione]] -> GR. FIANCO MANTELLO SX V. ZEUS SUP | G3: =RigheOfferte[[#This Row],[Q.ta'']] -> 2000 | H3: =RigheOfferte[[#This Row],[Lavorazione]] -> L1 | I3: =RigheOfferte[[#This Row],[Colore]] -> PS068 | J3: =RigheOfferte[[#This Row],[Velocità]] -> 2 | K3: =RigheOfferte[[#This Row],[Superf.pz Mq]] -> 0.721 | L3: =RigheOfferte[[#This Row],[passo]] -> 1.2 | M3: =RigheOfferte[[#This Row],[nr.pezzi Telaio]] -> 5 | N3: =RigheOfferte[[#This Row],[nr.pezzi ora-unita]] -> 500 | O3: =Tabella1[[#This Row],[superificie]]*Resa -> 0.1127644 | P3: =Tabella1[[#This Row],[KgPezzo]]*Tabella1[[#This Row],[q.ta offerta]] -> 225.5288 | Q3: =RigheOfferte[[#This Row],[QtaProtez]] -> 0 | R3: =RigheOfferte[[#This Row],[Tipo Protezione]] -> 0
A4: =RigheOfferte[[#This Row],[Nprev]] -> 202602 | B4: =RigheOfferte[[#This Row],[Nriga]] -> 2 | C4: =RigheOfferte[[#This Row],[Cliente]] -> IMMERGAS | D4: =RigheOfferte[[#This Row],[sub_cliente]] -> IMMERGAS | E4: =RigheOfferte[[#This Row],[cod.Art.]] -> 3037280 | F4: =RigheOfferte[[#This Row],[Descrizione]] -> GR. FIANCO MANTELLO SX V. ZEUS SUP | G4: =RigheOfferte[[#This Row],[Q.ta'']] -> 2000 | H4: =RigheOfferte[[#This Row],[Lavorazione]] -> MON | I4: =RigheOfferte[[#This Row],[Colore]] -> 0 | J4: =RigheOfferte[[#This Row],[Velocità]] -> 0 | K4: =RigheOfferte[[#This Row],[Superf.pz Mq]] -> 0 | L4: =RigheOfferte[[#This Row],[passo]] -> 0 | M4: =RigheOfferte[[#This Row],[nr.pezzi Telaio]] -> 0 | N4: =RigheOfferte[[#This Row],[nr.pezzi ora-unita]] -> 0 | O4: =Tabella1[[#This Row],[superificie]]*Resa -> 0 | P4: =Tabella1[[#This Row],[KgPezzo]]*Tabella1[[#This Row],[q.ta offerta]] -> 0 | Q4: =RigheOfferte[[#This Row],[QtaProtez]] -> 0 | R4: =RigheOfferte[[#This Row],[Tipo Protezione]] -> 0
A5: =RigheOfferte[[#This Row],[Nprev]] -> 202602 | B5: =RigheOfferte[[#This Row],[Nriga]] -> 3 | C5: =RigheOfferte[[#This Row],[Cliente]] -> IMMERGAS | D5: =RigheOfferte[[#This Row],[sub_cliente]] -> IMMERGAS | E5: =RigheOfferte[[#This Row],[cod.Art.]] -> 3037280 | F5: =RigheOfferte[[#This Row],[Descrizione]] -> GR. FIANCO MANTELLO SX V. ZEUS SUP | G5: =RigheOfferte[[#This Row],[Q.ta'']] -> 2000 | H5: =RigheOfferte[[#This Row],[Lavorazione]] -> IMB | I5: =RigheOfferte[[#This Row],[Colore]] -> 0 | J5: =RigheOfferte[[#This Row],[Velocità]] -> 0 | K5: =RigheOfferte[[#This Row],[Superf.pz Mq]] -> 0 | L5: =RigheOfferte[[#This Row],[passo]] -> 0 | M5: =RigheOfferte[[#This Row],[nr.pezzi Telaio]] -> 0 | N5: =RigheOfferte[[#This Row],[nr.pezzi ora-unita]] -> 0 | O5: =Tabella1[[#This Row],[superificie]]*Resa -> 0 | P5: =Tabella1[[#This Row],[KgPezzo]]*Tabella1[[#This Row],[q.ta offerta]] -> 0 | Q5: =RigheOfferte[[#This Row],[QtaProtez]] -> 0 | R5: =RigheOfferte[[#This Row],[Tipo Protezione]] -> 0
A6: =RigheOfferte[[#This Row],[Nprev]] -> 0 | B6: =RigheOfferte[[#This Row],[Nriga]] -> 0 | C6: =RigheOfferte[[#This Row],[Cliente]] -> 0 | D6: =RigheOfferte[[#This Row],[sub_cliente]] -> 0 | E6: =RigheOfferte[[#This Row],[cod.Art.]] -> 0 | F6: =RigheOfferte[[#This Row],[Descrizione]] -> 0 | G6: =RigheOfferte[[#This Row],[Q.ta'']] -> 0 | H6: =RigheOfferte[[#This Row],[Lavorazione]] -> 0 | I6: =RigheOfferte[[#This Row],[Colore]] -> 0 | J6: =RigheOfferte[[#This Row],[Velocità]] -> 0 | K6: =RigheOfferte[[#This Row],[Superf.pz Mq]] -> 0 | L6: =RigheOfferte[[#This Row],[passo]] -> 0 | M6: =RigheOfferte[[#This Row],[nr.pezzi Telaio]] -> 0 | N6: =RigheOfferte[[#This Row],[nr.pezzi ora-unita]] -> 0 | O6: =Tabella1[[#This Row],[superificie]]*Resa -> 0 | P6: =Tabella1[[#This Row],[KgPezzo]]*Tabella1[[#This Row],[q.ta offerta]] -> 0 | Q6: =RigheOfferte[[#This Row],[QtaProtez]] -> 0 | R6: =RigheOfferte[[#This Row],[Tipo Protezione]] -> 0
A7: =RigheOfferte[[#This Row],[Nprev]] -> 0 | B7: =RigheOfferte[[#This Row],[Nriga]] -> 0 | C7: =RigheOfferte[[#This Row],[Cliente]] -> 0 | D7: =RigheOfferte[[#This Row],[sub_cliente]] -> 0 | E7: =RigheOfferte[[#This Row],[cod.Art.]] -> 0 | F7: =RigheOfferte[[#This Row],[Descrizione]] -> 0 | G7: =RigheOfferte[[#This Row],[Q.ta'']] -> 0 | H7: =RigheOfferte[[#This Row],[Lavorazione]] -> 0 | I7: =RigheOfferte[[#This Row],[Colore]] -> 0 | J7: =RigheOfferte[[#This Row],[Velocità]] -> 0 | K7: =RigheOfferte[[#This Row],[Superf.pz Mq]] -> 0 | L7: =RigheOfferte[[#This Row],[passo]] -> 0 | M7: =RigheOfferte[[#This Row],[nr.pezzi Telaio]] -> 0 | N7: =RigheOfferte[[#This Row],[nr.pezzi ora-unita]] -> 0 | O7: =Tabella1[[#This Row],[superificie]]*Resa -> 0 | P7: =Tabella1[[#This Row],[KgPezzo]]*Tabella1[[#This Row],[q.ta offerta]] -> 0 | Q7: =RigheOfferte[[#This Row],[QtaProtez]] -> 0 | R7: =RigheOfferte[[#This Row],[Tipo Protezione]] -> 0
A8: =RigheOfferte[[#This Row],[Nprev]] -> 0 | B8: =RigheOfferte[[#This Row],[Nriga]] -> 0 | C8: =RigheOfferte[[#This Row],[Cliente]] -> 0 | D8: =RigheOfferte[[#This Row],[sub_cliente]] -> 0 | E8: =RigheOfferte[[#This Row],[cod.Art.]] -> 0 | F8: =RigheOfferte[[#This Row],[Descrizione]] -> 0 | G8: =RigheOfferte[[#This Row],[Q.ta'']] -> 0 | H8: =RigheOfferte[[#This Row],[Lavorazione]] -> 0 | I8: =RigheOfferte[[#This Row],[Colore]] -> 0 | J8: =RigheOfferte[[#This Row],[Velocità]] -> 0 | K8: =RigheOfferte[[#This Row],[Superf.pz Mq]] -> 0 | L8: =RigheOfferte[[#This Row],[passo]] -> 0 | M8: =RigheOfferte[[#This Row],[nr.pezzi Telaio]] -> 0 | N8: =RigheOfferte[[#This Row],[nr.pezzi ora-unita]] -> 0 | O8: =Tabella1[[#This Row],[superificie]]*Resa -> 0 | P8: =Tabella1[[#This Row],[KgPezzo]]*Tabella1[[#This Row],[q.ta offerta]] -> 0 | Q8: =RigheOfferte[[#This Row],[QtaProtez]] -> 0 | R8: =RigheOfferte[[#This Row],[Tipo Protezione]] -> 0
A9: =RigheOfferte[[#This Row],[Nprev]] -> 0 | B9: =RigheOfferte[[#This Row],[Nriga]] -> 0 | C9: =RigheOfferte[[#This Row],[Cliente]] -> 0 | D9: =RigheOfferte[[#This Row],[sub_cliente]] -> 0 | E9: =RigheOfferte[[#This Row],[cod.Art.]] -> 0 | F9: =RigheOfferte[[#This Row],[Descrizione]] -> 0 | G9: =RigheOfferte[[#This Row],[Q.ta'']] -> 0 | H9: =RigheOfferte[[#This Row],[Lavorazione]] -> 0 | I9: =RigheOfferte[[#This Row],[Colore]] -> 0 | J9: =RigheOfferte[[#This Row],[Velocità]] -> 0 | K9: =RigheOfferte[[#This Row],[Superf.pz Mq]] -> 0 | L9: =RigheOfferte[[#This Row],[passo]] -> 0 | M9: =RigheOfferte[[#This Row],[nr.pezzi Telaio]] -> 0 | N9: =RigheOfferte[[#This Row],[nr.pezzi ora-unita]] -> 0 | O9: =Tabella1[[#This Row],[superificie]]*Resa -> 0 | P9: =Tabella1[[#This Row],[KgPezzo]]*Tabella1[[#This Row],[q.ta offerta]] -> 0 | Q9: =RigheOfferte[[#This Row],[QtaProtez]] -> 0 | R9: =RigheOfferte[[#This Row],[Tipo Protezione]] -> 0
A10: =RigheOfferte[[#This Row],[Nprev]] -> 0 | B10: =RigheOfferte[[#This Row],[Nriga]] -> 0 | C10: =RigheOfferte[[#This Row],[Cliente]] -> 0 | D10: =RigheOfferte[[#This Row],[sub_cliente]] -> 0 | E10: =RigheOfferte[[#This Row],[cod.Art.]] -> 0 | F10: =RigheOfferte[[#This Row],[Descrizione]] -> 0 | G10: =RigheOfferte[[#This Row],[Q.ta'']] -> 0 | H10: =RigheOfferte[[#This Row],[Lavorazione]] -> 0 | I10: =RigheOfferte[[#This Row],[Colore]] -> 0 | J10: =RigheOfferte[[#This Row],[Velocità]] -> 0 | K10: =RigheOfferte[[#This Row],[Superf.pz Mq]] -> 0 | L10: =RigheOfferte[[#This Row],[passo]] -> 0 | M10: =RigheOfferte[[#This Row],[nr.pezzi Telaio]] -> 0 | N10: =RigheOfferte[[#This Row],[nr.pezzi ora-unita]] -> 0 | O10: =Tabella1[[#This Row],[superificie]]*Resa -> 0 | P10: =Tabella1[[#This Row],[KgPezzo]]*Tabella1[[#This Row],[q.ta offerta]] -> 0 | Q10: =RigheOfferte[[#This Row],[QtaProtez]] -> 0 | R10: =RigheOfferte[[#This Row],[Tipo Protezione]] -> 0
A11: =RigheOfferte[[#This Row],[Nprev]] -> 0 | B11: =RigheOfferte[[#This Row],[Nriga]] -> 0 | C11: =RigheOfferte[[#This Row],[Cliente]] -> 0 | D11: =RigheOfferte[[#This Row],[sub_cliente]] -> 0 | E11: =RigheOfferte[[#This Row],[cod.Art.]] -> 0 | F11: =RigheOfferte[[#This Row],[Descrizione]] -> 0 | G11: =RigheOfferte[[#This Row],[Q.ta'']] -> 0 | H11: =RigheOfferte[[#This Row],[Lavorazione]] -> 0 | I11: =RigheOfferte[[#This Row],[Colore]] -> 0 | J11: =RigheOfferte[[#This Row],[Velocità]] -> 0 | K11: =RigheOfferte[[#This Row],[Superf.pz Mq]] -> 0 | L11: =RigheOfferte[[#This Row],[passo]] -> 0 | M11: =RigheOfferte[[#This Row],[nr.pezzi Telaio]] -> 0 | N11: =RigheOfferte[[#This Row],[nr.pezzi ora-unita]] -> 0 | O11: =Tabella1[[#This Row],[superificie]]*Resa -> 0 | P11: =Tabella1[[#This Row],[KgPezzo]]*Tabella1[[#This Row],[q.ta offerta]] -> 0 | Q11: =RigheOfferte[[#This Row],[QtaProtez]] -> 0 | R11: =RigheOfferte[[#This Row],[Tipo Protezione]] -> 0
A12: =RigheOfferte[[#This Row],[Nprev]] -> 0 | B12: =RigheOfferte[[#This Row],[Nriga]] -> 0 | C12: =RigheOfferte[[#This Row],[Cliente]] -> 0 | D12: =RigheOfferte[[#This Row],[sub_cliente]] -> 0 | E12: =RigheOfferte[[#This Row],[cod.Art.]] -> 0 | F12: =RigheOfferte[[#This Row],[Descrizione]] -> 0 | G12: =RigheOfferte[[#This Row],[Q.ta'']] -> 0 | H12: =RigheOfferte[[#This Row],[Lavorazione]] -> 0 | I12: =RigheOfferte[[#This Row],[Colore]] -> 0 | J12: =RigheOfferte[[#This Row],[Velocità]] -> 0 | K12: =RigheOfferte[[#This Row],[Superf.pz Mq]] -> 0 | L12: =RigheOfferte[[#This Row],[passo]] -> 0 | M12: =RigheOfferte[[#This Row],[nr.pezzi Telaio]] -> 0 | N12: =RigheOfferte[[#This Row],[nr.pezzi ora-unita]] -> 0 | O12: =Tabella1[[#This Row],[superificie]]*Resa -> 0 | P12: =Tabella1[[#This Row],[KgPezzo]]*Tabella1[[#This Row],[q.ta offerta]] -> 0 | Q12: =RigheOfferte[[#This Row],[QtaProtez]] -> 0 | R12: =RigheOfferte[[#This Row],[Tipo Protezione]] -> 0
A13: =RigheOfferte[[#This Row],[Nprev]] -> 0 | B13: =RigheOfferte[[#This Row],[Nriga]] -> 0 | C13: =RigheOfferte[[#This Row],[Cliente]] -> 0 | D13: =RigheOfferte[[#This Row],[sub_cliente]] -> 0 | E13: =RigheOfferte[[#This Row],[cod.Art.]] -> 0 | F13: =RigheOfferte[[#This Row],[Descrizione]] -> 0 | G13: =RigheOfferte[[#This Row],[Q.ta'']] -> 0 | H13: =RigheOfferte[[#This Row],[Lavorazione]] -> 0 | I13: =RigheOfferte[[#This Row],[Colore]] -> 0 | J13: =RigheOfferte[[#This Row],[Velocità]] -> 0 | K13: =RigheOfferte[[#This Row],[Superf.pz Mq]] -> 0 | L13: =RigheOfferte[[#This Row],[passo]] -> 0 | M13: =RigheOfferte[[#This Row],[nr.pezzi Telaio]] -> 0 | N13: =RigheOfferte[[#This Row],[nr.pezzi ora-unita]] -> 0 | O13: =Tabella1[[#This Row],[superificie]]*Resa -> 0 | P13: =Tabella1[[#This Row],[KgPezzo]]*Tabella1[[#This Row],[q.ta offerta]] -> 0 | Q13: =RigheOfferte[[#This Row],[QtaProtez]] -> 0 | R13: =RigheOfferte[[#This Row],[Tipo Protezione]] -> 0
... A1242: =RigheOfferte[[#This Row],[Nprev]] -> #VALUE! | B1242: =RigheOfferte[[#This Row],[Nriga]] -> #VALUE! | C1242: =RigheOfferte[[#This Row],[Cliente]] -> #VALUE! | D1242: =RigheOfferte[[#This Row],[sub_cliente]] -> #VALUE! | E1242: =RigheOfferte[[#This Row],[cod.Art.]] -> #VALUE! | F1242: =RigheOfferte[[#This Row],[Descrizione]] -> #VALUE! | G1242: =RigheOfferte[[#This Row],[Q.ta'']] -> #VALUE! | H1242: =RigheOfferte[[#This Row],[Lavorazione]] -> #VALUE! | I1242: =RigheOfferte[[#This Row],[Colore]] -> #VALUE! | J1242: =RigheOfferte[[#This Row],[Velocità]] -> #VALUE! | K1242: =RigheOfferte[[#This Row],[Superf.pz Mq]] -> #VALUE! | L1242: =RigheOfferte[[#This Row],[passo]] -> #VALUE! | M1242: =RigheOfferte[[#This Row],[nr.pezzi Telaio]] -> #VALUE! | N1242: =RigheOfferte[[#This Row],[nr.pezzi ora-unita]] -> #VALUE! | O1242: =Tabella1[[#This Row],[superificie]]*Resa -> #VALUE! | P1242: =Tabella1[[#This Row],[KgPezzo]]*Tabella1[[#This Row],[q.ta offerta]] -> #VALUE! | Q1242: =RigheOfferte[[#This Row],[QtaProtez]] -> #VALUE! | R1242: =RigheOfferte[[#This Row],[Tipo Protezione]] -> #VALUE!

Sheet riepilogo prezzi
A1: CodCombi | B1: mese | C1: Quadrimestre | D1: Nprev | E1: Nriga | F1: data | G1: Cliente | H1: sub_cliente | I1: Confermato | J1: Disegno | K1: cod.Art. | L1: Descrizione | M1: Lavorazione | N1: Desc Lavorazione | O1: Cod Vel | P1: Velocità | Q1: Colore | R1: Q.ta' | S1: lotto | T1: passo | U1: nr.pezzi Telaio | V1: nr.pezzi ora-unita | W1: Pz Ora Altre Lav | X1: ORE LAVOR | Y1: cambio colore su pezzo | Z1: costo orario | AA1: Superf.pz Mq | AB1: MP (€kg) | AC1: tot.CMP pz | AD1: QtaProtez | AE1: Tipo Protezione | AF1: Costo Prot | AG1: altri costi | AH1: costo industriale pz | AI1: totale costi | AJ1: Ricarico | AK1: Prezzo Di Vendita | AL1: TotaleOfferta | AM1: prezzo Mq
A2: =IF(LEN('riepilogo prezzi'!$D2&'riepilogo prezzi'!$E2)>0,'riepilogo prezzi'!$D2&"-"&'riepilogo prezzi'!$E2,"") -> 202601-1 | B2: =IF(LEN(MONTH(RigheOfferte[[#This Row],[data]]))=1,0&MONTH(RigheOfferte[[#This Row],[data]]),MONTH(RigheOfferte[[#This Row],[data]])) -> 01 | C2: =IF(MONTH(RigheOfferte[[#This Row],[data]])>8,"03",IF(MONTH(RigheOfferte[[#This Row],[data]])>4,"02","01")) -> 01 | D2: 202601 | E2: 1 | F2: 46029 | G2: VERONA LAMIERE | H2: FRANKE | I2: IN ATTESA | J2: PREVENTIVI 2026 DATI E PDF\PREV 202602\560.0755.201 mounting bracket valve group themoblock.pdf | K2: 5600755201 | L2: Mounting bracket valve group thermoblock | M2: L1 | N2: =_xlfn.IFNA(VLOOKUP(RigheOfferte[[#This Row],[Lavorazione]],DescLavorazioni[],2,FALSE),"") -> Verniciatura | O2: F3 | P2: =_xlfn.IFNA(VLOOKUP(RigheOfferte[[#This Row],[Cod Vel]],VeloCatena[],3,FALSE),0) -> 2 | Q2: P90005XLOP | R2: 1000 | S2: 1001-oltre | T2: 0.8 | U2: 16 | V2: =IF(RigheOfferte[[#This Row],[Velocità]]>0,60*RigheOfferte[[#This Row],[Velocità]]/RigheOfferte[[#This Row],[passo]]*RigheOfferte[[#This Row],[nr.pezzi Telaio]],0) -> 2400 | X2: =IFERROR(IF(OR(RigheOfferte[[#This Row],[Lavorazione]]="L1",RigheOfferte[[#This Row],[Lavorazione]]="L2",RigheOfferte[[#This Row],[Lavorazione]]="L3"),RigheOfferte[[#This Row],[Q.ta'']]/RigheOfferte[[#This Row],[nr.pezzi ora-unita]],RigheOfferte[[#This Row],[Q.ta'']]/RigheOfferte[[#This Row],[Pz Ora Altre Lav]]),0) -> 0.41666667 | Y2: =IFERROR(IF(OR(RigheOfferte[[#This Row],[Lavorazione]]="L1",RigheOfferte[[#This Row],[Lavorazione]]="L2",RigheOfferte[[#This Row],[Lavorazione]]="L3"),VLOOKUP(RigheOfferte[[#This Row],[lotto]],Lotti[],2,FALSE),0),0) -> 30 | Z2: =_xlfn.IFNA(INDEX(RiepilogoCostiOrari[],MATCH(YEAR(RigheOfferte[[#This Row],[data]])&RigheOfferte[[#This Row],[Quadrimestre]],QuCostiLav,0),MATCH(RigheOfferte[[#This Row],[Lavorazione]],CodLavorazioni,0)),0) -> 690.7 | AA2: 0.057 | AB2: 5 | AC2: =RigheOfferte[[#This Row],[Superf.pz Mq]]*Resa*RigheOfferte[[#This Row],[MP (€kg)]] -> 0.044574 | AF2: =_xlfn.IFNA(VLOOKUP(RigheOfferte[[#This Row],[Tipo Protezione]],Protezioni[],2,FALSE),0) -> 0 | AG2: 0.51 | AH2: =IFERROR((RigheOfferte[[#This Row],[ORE LAVOR]]*RigheOfferte[[#This Row],[costo orario]]/RigheOfferte[[#This Row],[Q.ta'']])+(RigheOfferte[[#This Row],[cambio colore su pezzo]]/RigheOfferte[[#This Row],[Q.ta'']])+(RigheOfferte[[#This Row],[QtaProtez]]*RigheOfferte[[#This Row],[Costo Prot]])+RigheOfferte[[#This Row],[tot.CMP pz]],0) -> 0.36236567 | AI2: =RigheOfferte[[#This Row],[altri costi]]+RigheOfferte[[#This Row],[costo industriale pz]] -> 0.87236567 | AJ2: =_xlfn.IFNA(INDEX(Ricarichi[],MATCH(YEAR(RigheOfferte[[#This Row],[data]])&RigheOfferte[[#This Row],[Quadrimestre]],QuCostiLav,0),MATCH(RigheOfferte[[#This Row],[Lavorazione]],CodLavorazioni,0)),0) -> 0.38 | AK2: =RigheOfferte[[#This Row],[totale costi]]+(RigheOfferte[[#This Row],[totale costi]]*RigheOfferte[[#This Row],[Ricarico]]) -> 1.2038646 | AL2: =RigheOfferte[[#This Row],[Prezzo Di Vendita]]*RigheOfferte[[#This Row],[Q.ta'']] -> 1203.8646 | AM2: =IFERROR(RigheOfferte[[#This Row],[Prezzo Di Vendita]]/RigheOfferte[[#This Row],[Superf.pz Mq]],0) -> 21.120432
A3: =IF(LEN('riepilogo prezzi'!$D3&'riepilogo prezzi'!$E3)>0,'riepilogo prezzi'!$D3&"-"&'riepilogo prezzi'!$E3,"") -> 202602-1 | B3: =IF(LEN(MONTH(RigheOfferte[[#This Row],[data]]))=1,0&MONTH(RigheOfferte[[#This Row],[data]]),MONTH(RigheOfferte[[#This Row],[data]])) -> 02 | C3: =IF(MONTH(RigheOfferte[[#This Row],[data]])>8,"03",IF(MONTH(RigheOfferte[[#This Row],[data]])>4,"02","01")) -> 01 | D3: 202602 | E3: 1 | F3: 46079 | G3: IMMERGAS | H3: IMMERGAS | I3: IN ATTESA | J3: PREV 202602\3.037280.pdf | K3: 3037280 | L3: GR. FIANCO MANTELLO SX V. ZEUS SUP | M3: L1 | N3: =_xlfn.IFNA(VLOOKUP(RigheOfferte[[#This Row],[Lavorazione]],DescLavorazioni[],2,FALSE),"") -> Verniciatura | O3: F3 | P3: =_xlfn.IFNA(VLOOKUP(RigheOfferte[[#This Row],[Cod Vel]],VeloCatena[],3,FALSE),0) -> 2 | Q3: PS068 | R3: 2000 | S3: ZERO | T3: 1.2 | U3: 5 | V3: =IF(RigheOfferte[[#This Row],[Velocità]]>0,60*RigheOfferte[[#This Row],[Velocità]]/RigheOfferte[[#This Row],[passo]]*RigheOfferte[[#This Row],[nr.pezzi Telaio]],0) -> 500 | X3: =IFERROR(IF(OR(RigheOfferte[[#This Row],[Lavorazione]]="L1",RigheOfferte[[#This Row],[Lavorazione]]="L2",RigheOfferte[[#This Row],[Lavorazione]]="L3"),RigheOfferte[[#This Row],[Q.ta'']]/RigheOfferte[[#This Row],[nr.pezzi ora-unita]],RigheOfferte[[#This Row],[Q.ta'']]/RigheOfferte[[#This Row],[Pz Ora Altre Lav]]),0) -> 4 | Y3: =IFERROR(IF(OR(RigheOfferte[[#This Row],[Lavorazione]]="L1",RigheOfferte[[#This Row],[Lavorazione]]="L2",RigheOfferte[[#This Row],[Lavorazione]]="L3"),VLOOKUP(RigheOfferte[[#This Row],[lotto]],Lotti[],2,FALSE),0),0) -> 10 | Z3: =_xlfn.IFNA(INDEX(RiepilogoCostiOrari[],MATCH(YEAR(RigheOfferte[[#This Row],[data]])&RigheOfferte[[#This Row],[Quadrimestre]],QuCostiLav,0),MATCH(RigheOfferte[[#This Row],[Lavorazione]],CodLavorazioni,0)),0) -> 690.7 | AA3: 0.721 | AB3: 4.6 | AC3: =RigheOfferte[[#This Row],[Superf.pz Mq]]*Resa*RigheOfferte[[#This Row],[MP (€kg)]] -> 0.51871624 | AF3: =_xlfn.IFNA(VLOOKUP(RigheOfferte[[#This Row],[Tipo Protezione]],Protezioni[],2,FALSE),0) -> 0 | AH3: =IFERROR((RigheOfferte[[#This Row],[ORE LAVOR]]*RigheOfferte[[#This Row],[costo orario]]/RigheOfferte[[#This Row],[Q.ta'']])+(RigheOfferte[[#This Row],[cambio colore su pezzo]]/RigheOfferte[[#This Row],[Q.ta'']])+(RigheOfferte[[#This Row],[QtaProtez]]*RigheOfferte[[#This Row],[Costo Prot]])+RigheOfferte[[#This Row],[tot.CMP pz]],0) -> 1.9051162 | AI3: =RigheOfferte[[#This Row],[altri costi]]+RigheOfferte[[#This Row],[costo industriale pz]] -> 1.9051162 | AJ3: =_xlfn.IFNA(INDEX(Ricarichi[],MATCH(YEAR(RigheOfferte[[#This Row],[data]])&RigheOfferte[[#This Row],[Quadrimestre]],QuCostiLav,0),MATCH(RigheOfferte[[#This Row],[Lavorazione]],CodLavorazioni,0)),0) -> 0.38 | AK3: =RigheOfferte[[#This Row],[totale costi]]+(RigheOfferte[[#This Row],[totale costi]]*RigheOfferte[[#This Row],[Ricarico]]) -> 2.6290604 | AL3: =RigheOfferte[[#This Row],[Prezzo Di Vendita]]*RigheOfferte[[#This Row],[Q.ta'']] -> 5258.1208 | AM3: =IFERROR(RigheOfferte[[#This Row],[Prezzo Di Vendita]]/RigheOfferte[[#This Row],[Superf.pz Mq]],0) -> 3.6464083
A4: =IF(LEN('riepilogo prezzi'!$D4&'riepilogo prezzi'!$E4)>0,'riepilogo prezzi'!$D4&"-"&'riepilogo prezzi'!$E4,"") -> 202602-2 | B4: =IF(LEN(MONTH(RigheOfferte[[#This Row],[data]]))=1,0&MONTH(RigheOfferte[[#This Row],[data]]),MONTH(RigheOfferte[[#This Row],[data]])) -> 02 | C4: =IF(MONTH(RigheOfferte[[#This Row],[data]])>8,"03",IF(MONTH(RigheOfferte[[#This Row],[data]])>4,"02","01")) -> 01 | D4: 202602 | E4: 2 | F4: 46079 | G4: IMMERGAS | H4: IMMERGAS | I4: IN ATTESA | J4: PREV 202602\3.037280.pdf | K4: 3037280 | L4: GR. FIANCO MANTELLO SX V. ZEUS SUP | M4: MON | N4: =_xlfn.IFNA(VLOOKUP(RigheOfferte[[#This Row],[Lavorazione]],DescLavorazioni[],2,FALSE),"") -> Montaggio | P4: =_xlfn.IFNA(VLOOKUP(RigheOfferte[[#This Row],[Cod Vel]],VeloCatena[],3,FALSE),0) -> 0 | R4: 2000 | V4: =IF(RigheOfferte[[#This Row],[Velocità]]>0,60*RigheOfferte[[#This Row],[Velocità]]/RigheOfferte[[#This Row],[passo]]*RigheOfferte[[#This Row],[nr.pezzi Telaio]],0) -> 0 | W4: 32 | X4: =IFERROR(IF(OR(RigheOfferte[[#This Row],[Lavorazione]]="L1",RigheOfferte[[#This Row],[Lavorazione]]="L2",RigheOfferte[[#This Row],[Lavorazione]]="L3"),RigheOfferte[[#This Row],[Q.ta'']]/RigheOfferte[[#This Row],[nr.pezzi ora-unita]],RigheOfferte[[#This Row],[Q.ta'']]/RigheOfferte[[#This Row],[Pz Ora Altre Lav]]),0) -> 62.5 | Y4: =IFERROR(IF(OR(RigheOfferte[[#This Row],[Lavorazione]]="L1",RigheOfferte[[#This Row],[Lavorazione]]="L2",RigheOfferte[[#This Row],[Lavorazione]]="L3"),VLOOKUP(RigheOfferte[[#This Row],[lotto]],Lotti[],2,FALSE),0),0) -> 0 | Z4: =_xlfn.IFNA(INDEX(RiepilogoCostiOrari[],MATCH(YEAR(RigheOfferte[[#This Row],[data]])&RigheOfferte[[#This Row],[Quadrimestre]],QuCostiLav,0),MATCH(RigheOfferte[[#This Row],[Lavorazione]],CodLavorazioni,0)),0) -> 30 | AC4: =RigheOfferte[[#This Row],[Superf.pz Mq]]*Resa*RigheOfferte[[#This Row],[MP (€kg)]] -> 0 | AF4: =_xlfn.IFNA(VLOOKUP(RigheOfferte[[#This Row],[Tipo Protezione]],Protezioni[],2,FALSE),0) -> 0 | AH4: =IFERROR((RigheOfferte[[#This Row],[ORE LAVOR]]*RigheOfferte[[#This Row],[costo orario]]/RigheOfferte[[#This Row],[Q.ta'']])+(RigheOfferte[[#This Row],[cambio colore su pezzo]]/RigheOfferte[[#This Row],[Q.ta'']])+(RigheOfferte[[#This Row],[QtaProtez]]*RigheOfferte[[#This Row],[Costo Prot]])+RigheOfferte[[#This Row],[tot.CMP pz]],0) -> 0.9375 | AI4: =RigheOfferte[[#This Row],[altri costi]]+RigheOfferte[[#This Row],[costo industriale pz]] -> 0.9375 | AJ4: =_xlfn.IFNA(INDEX(Ricarichi[],MATCH(YEAR(RigheOfferte[[#This Row],[data]])&RigheOfferte[[#This Row],[Quadrimestre]],QuCostiLav,0),MATCH(RigheOfferte[[#This Row],[Lavorazione]],CodLavorazioni,0)),0) -> 0.38 | AK4: =RigheOfferte[[#This Row],[totale costi]]+(RigheOfferte[[#This Row],[totale costi]]*RigheOfferte[[#This Row],[Ricarico]]) -> 1.29375 | AL4: =RigheOfferte[[#This Row],[Prezzo Di Vendita]]*RigheOfferte[[#This Row],[Q.ta'']] -> 2587.5 | AM4: =IFERROR(RigheOfferte[[#This Row],[Prezzo Di Vendita]]/RigheOfferte[[#This Row],[Superf.pz Mq]],0) -> 0
A5: =IF(LEN('riepilogo prezzi'!$D5&'riepilogo prezzi'!$E5)>0,'riepilogo prezzi'!$D5&"-"&'riepilogo prezzi'!$E5,"") -> 202602-3 | B5: =IF(LEN(MONTH(RigheOfferte[[#This Row],[data]]))=1,0&MONTH(RigheOfferte[[#This Row],[data]]),MONTH(RigheOfferte[[#This Row],[data]])) -> 02 | C5: =IF(MONTH(RigheOfferte[[#This Row],[data]])>8,"03",IF(MONTH(RigheOfferte[[#This Row],[data]])>4,"02","01")) -> 01 | D5: 202602 | E5: 3 | F5: 46079 | G5: IMMERGAS | H5: IMMERGAS | I5: IN ATTESA | J5: PREV 202602\3.037280.pdf | K5: 3037280 | L5: GR. FIANCO MANTELLO SX V. ZEUS SUP | M5: IMB | N5: =_xlfn.IFNA(VLOOKUP(RigheOfferte[[#This Row],[Lavorazione]],DescLavorazioni[],2,FALSE),"") -> Imballo | P5: =_xlfn.IFNA(VLOOKUP(RigheOfferte[[#This Row],[Cod Vel]],VeloCatena[],3,FALSE),0) -> 0 | R5: 2000 | V5: =IF(RigheOfferte[[#This Row],[Velocità]]>0,60*RigheOfferte[[#This Row],[Velocità]]/RigheOfferte[[#This Row],[passo]]*RigheOfferte[[#This Row],[nr.pezzi Telaio]],0) -> 0 | W5: 250 | X5: =IFERROR(IF(OR(RigheOfferte[[#This Row],[Lavorazione]]="L1",RigheOfferte[[#This Row],[Lavorazione]]="L2",RigheOfferte[[#This Row],[Lavorazione]]="L3"),RigheOfferte[[#This Row],[Q.ta'']]/RigheOfferte[[#This Row],[nr.pezzi ora-unita]],RigheOfferte[[#This Row],[Q.ta'']]/RigheOfferte[[#This Row],[Pz Ora Altre Lav]]),0) -> 8 | Y5: =IFERROR(IF(OR(RigheOfferte[[#This Row],[Lavorazione]]="L1",RigheOfferte[[#This Row],[Lavorazione]]="L2",RigheOfferte[[#This Row],[Lavorazione]]="L3"),VLOOKUP(RigheOfferte[[#This Row],[lotto]],Lotti[],2,FALSE),0),0) -> 0 | Z5: =_xlfn.IFNA(INDEX(RiepilogoCostiOrari[],MATCH(YEAR(RigheOfferte[[#This Row],[data]])&RigheOfferte[[#This Row],[Quadrimestre]],QuCostiLav,0),MATCH(RigheOfferte[[#This Row],[Lavorazione]],CodLavorazioni,0)),0) -> 30 | AC5: =RigheOfferte[[#This Row],[Superf.pz Mq]]*Resa*RigheOfferte[[#This Row],[MP (€kg)]] -> 0 | AF5: =_xlfn.IFNA(VLOOKUP(RigheOfferte[[#This Row],[Tipo Protezione]],Protezioni[],2,FALSE),0) -> 0 | AH5: =IFERROR((RigheOfferte[[#This Row],[ORE LAVOR]]*RigheOfferte[[#This Row],[costo orario]]/RigheOfferte[[#This Row],[Q.ta'']])+(RigheOfferte[[#This Row],[cambio colore su pezzo]]/RigheOfferte[[#This Row],[Q.ta'']])+(RigheOfferte[[#This Row],[QtaProtez]]*RigheOfferte[[#This Row],[Costo Prot]])+RigheOfferte[[#This Row],[tot.CMP pz]],0) -> 0.12 | AI5: =RigheOfferte[[#This Row],[altri costi]]+RigheOfferte[[#This Row],[costo industriale pz]] -> 0.12 | AJ5: =_xlfn.IFNA(INDEX(Ricarichi[],MATCH(YEAR(RigheOfferte[[#This Row],[data]])&RigheOfferte[[#This Row],[Quadrimestre]],QuCostiLav,0),MATCH(RigheOfferte[[#This Row],[Lavorazione]],CodLavorazioni,0)),0) -> 0.38 | AK5: =RigheOfferte[[#This Row],[totale costi]]+(RigheOfferte[[#This Row],[totale costi]]*RigheOfferte[[#This Row],[Ricarico]]) -> 0.1656 | AL5: =RigheOfferte[[#This Row],[Prezzo Di Vendita]]*RigheOfferte[[#This Row],[Q.ta'']] -> 331.2 | AM5: =IFERROR(RigheOfferte[[#This Row],[Prezzo Di Vendita]]/RigheOfferte[[#This Row],[Superf.pz Mq]],0) -> 0
A6: =IF(LEN('riepilogo prezzi'!$D6&'riepilogo prezzi'!$E6)>0,'riepilogo prezzi'!$D6&"-"&'riepilogo prezzi'!$E6,"") | B6: =IF(LEN(MONTH(RigheOfferte[[#This Row],[data]]))=1,0&MONTH(RigheOfferte[[#This Row],[data]]),MONTH(RigheOfferte[[#This Row],[data]])) -> 01 | C6: =IF(MONTH(RigheOfferte[[#This Row],[data]])>8,"03",IF(MONTH(RigheOfferte[[#This Row],[data]])>4,"02","01")) -> 01 | N6: =_xlfn.IFNA(VLOOKUP(RigheOfferte[[#This Row],[Lavorazione]],DescLavorazioni[],2,FALSE),"") | P6: =_xlfn.IFNA(VLOOKUP(RigheOfferte[[#This Row],[Cod Vel]],VeloCatena[],3,FALSE),0) -> 0 | V6: =IF(RigheOfferte[[#This Row],[Velocità]]>0,60*RigheOfferte[[#This Row],[Velocità]]/RigheOfferte[[#This Row],[passo]]*RigheOfferte[[#This Row],[nr.pezzi Telaio]],0) -> 0 | X6: =IFERROR(IF(OR(RigheOfferte[[#This Row],[Lavorazione]]="L1",RigheOfferte[[#This Row],[Lavorazione]]="L2",RigheOfferte[[#This Row],[Lavorazione]]="L3"),RigheOfferte[[#This Row],[Q.ta'']]/RigheOfferte[[#This Row],[nr.pezzi ora-unita]],RigheOfferte[[#This Row],[Q.ta'']]/RigheOfferte[[#This Row],[Pz Ora Altre Lav]]),0) -> 0 | Y6: =IFERROR(IF(OR(RigheOfferte[[#This Row],[Lavorazione]]="L1",RigheOfferte[[#This Row],[Lavorazione]]="L2",RigheOfferte[[#This Row],[Lavorazione]]="L3"),VLOOKUP(RigheOfferte[[#This Row],[lotto]],Lotti[],2,FALSE),0),0) -> 0 | Z6: =_xlfn.IFNA(INDEX(RiepilogoCostiOrari[],MATCH(YEAR(RigheOfferte[[#This Row],[data]])&RigheOfferte[[#This Row],[Quadrimestre]],QuCostiLav,0),MATCH(RigheOfferte[[#This Row],[Lavorazione]],CodLavorazioni,0)),0) -> 0 | AC6: =RigheOfferte[[#This Row],[Superf.pz Mq]]*Resa*RigheOfferte[[#This Row],[MP (€kg)]] -> 0 | AF6: =_xlfn.IFNA(VLOOKUP(RigheOfferte[[#This Row],[Tipo Protezione]],Protezioni[],2,FALSE),0) -> 0 | AH6: =IFERROR((RigheOfferte[[#This Row],[ORE LAVOR]]*RigheOfferte[[#This Row],[costo orario]]/RigheOfferte[[#This Row],[Q.ta'']])+(RigheOfferte[[#This Row],[cambio colore su pezzo]]/RigheOfferte[[#This Row],[Q.ta'']])+(RigheOfferte[[#This Row],[QtaProtez]]*RigheOfferte[[#This Row],[Costo Prot]])+RigheOfferte[[#This Row],[tot.CMP pz]],0) -> 0 | AI6: =RigheOfferte[[#This Row],[altri costi]]+RigheOfferte[[#This Row],[costo industriale pz]] -> 0 | AJ6: =_xlfn.IFNA(INDEX(Ricarichi[],MATCH(YEAR(RigheOfferte[[#This Row],[data]])&RigheOfferte[[#This Row],[Quadrimestre]],QuCostiLav,0),MATCH(RigheOfferte[[#This Row],[Lavorazione]],CodLavorazioni,0)),0) -> 0 | AK6: =RigheOfferte[[#This Row],[totale costi]]+(RigheOfferte[[#This Row],[totale costi]]*RigheOfferte[[#This Row],[Ricarico]]) -> 0 | AL6: =RigheOfferte[[#This Row],[Prezzo Di Vendita]]*RigheOfferte[[#This Row],[Q.ta'']] -> 0 | AM6: =IFERROR(RigheOfferte[[#This Row],[Prezzo Di Vendita]]/RigheOfferte[[#This Row],[Superf.pz Mq]],0) -> 0
A7: =IF(LEN('riepilogo prezzi'!$D7&'riepilogo prezzi'!$E7)>0,'riepilogo prezzi'!$D7&"-"&'riepilogo prezzi'!$E7,"") | B7: =IF(LEN(MONTH(RigheOfferte[[#This Row],[data]]))=1,0&MONTH(RigheOfferte[[#This Row],[data]]),MONTH(RigheOfferte[[#This Row],[data]])) -> 01 | C7: =IF(MONTH(RigheOfferte[[#This Row],[data]])>8,"03",IF(MONTH(RigheOfferte[[#This Row],[data]])>4,"02","01")) -> 01 | N7: =_xlfn.IFNA(VLOOKUP(RigheOfferte[[#This Row],[Lavorazione]],DescLavorazioni[],2,FALSE),"") | P7: =_xlfn.IFNA(VLOOKUP(RigheOfferte[[#This Row],[Cod Vel]],VeloCatena[],3,FALSE),0) -> 0 | V7: =IF(RigheOfferte[[#This Row],[Velocità]]>0,60*RigheOfferte[[#This Row],[Velocità]]/RigheOfferte[[#This Row],[passo]]*RigheOfferte[[#This Row],[nr.pezzi Telaio]],0) -> 0 | X7: =IFERROR(IF(OR(RigheOfferte[[#This Row],[Lavorazione]]="L1",RigheOfferte[[#This Row],[Lavorazione]]="L2",RigheOfferte[[#This Row],[Lavorazione]]="L3"),RigheOfferte[[#This Row],[Q.ta'']]/RigheOfferte[[#This Row],[nr.pezzi ora-unita]],RigheOfferte[[#This Row],[Q.ta'']]/RigheOfferte[[#This Row],[Pz Ora Altre Lav]]),0) -> 0 | Y7: =IFERROR(IF(OR(RigheOfferte[[#This Row],[Lavorazione]]="L1",RigheOfferte[[#This Row],[Lavorazione]]="L2",RigheOfferte[[#This Row],[Lavorazione]]="L3"),VLOOKUP(RigheOfferte[[#This Row],[lotto]],Lotti[],2,FALSE),0),0) -> 0 | Z7: =_xlfn.IFNA(INDEX(RiepilogoCostiOrari[],MATCH(YEAR(RigheOfferte[[#This Row],[data]])&RigheOfferte[[#This Row],[Quadrimestre]],QuCostiLav,0),MATCH(RigheOfferte[[#This Row],[Lavorazione]],CodLavorazioni,0)),0) -> 0 | AC7: =RigheOfferte[[#This Row],[Superf.pz Mq]]*Resa*RigheOfferte[[#This Row],[MP (€kg)]] -> 0 | AF7: =_xlfn.IFNA(VLOOKUP(RigheOfferte[[#This Row],[Tipo Protezione]],Protezioni[],2,FALSE),0) -> 0 | AH7: =IFERROR((RigheOfferte[[#This Row],[ORE LAVOR]]*RigheOfferte[[#This Row],[costo orario]]/RigheOfferte[[#This Row],[Q.ta'']])+(RigheOfferte[[#This Row],[cambio colore su pezzo]]/RigheOfferte[[#This Row],[Q.ta'']])+(RigheOfferte[[#This Row],[QtaProtez]]*RigheOfferte[[#This Row],[Costo Prot]])+RigheOfferte[[#This Row],[tot.CMP pz]],0) -> 0 | AI7: =RigheOfferte[[#This Row],[altri costi]]+RigheOfferte[[#This Row],[costo industriale pz]] -> 0 | AJ7: =_xlfn.IFNA(INDEX(Ricarichi[],MATCH(YEAR(RigheOfferte[[#This Row],[data]])&RigheOfferte[[#This Row],[Quadrimestre]],QuCostiLav,0),MATCH(RigheOfferte[[#This Row],[Lavorazione]],CodLavorazioni,0)),0) -> 0 | AK7: =RigheOfferte[[#This Row],[totale costi]]+(RigheOfferte[[#This Row],[totale costi]]*RigheOfferte[[#This Row],[Ricarico]]) -> 0 | AL7: =RigheOfferte[[#This Row],[Prezzo Di Vendita]]*RigheOfferte[[#This Row],[Q.ta'']] -> 0 | AM7: =IFERROR(RigheOfferte[[#This Row],[Prezzo Di Vendita]]/RigheOfferte[[#This Row],[Superf.pz Mq]],0) -> 0
A8: =IF(LEN('riepilogo prezzi'!$D8&'riepilogo prezzi'!$E8)>0,'riepilogo prezzi'!$D8&"-"&'riepilogo prezzi'!$E8,"") | B8: =IF(LEN(MONTH(RigheOfferte[[#This Row],[data]]))=1,0&MONTH(RigheOfferte[[#This Row],[data]]),MONTH(RigheOfferte[[#This Row],[data]])) -> 01 | C8: =IF(MONTH(RigheOfferte[[#This Row],[data]])>8,"03",IF(MONTH(RigheOfferte[[#This Row],[data]])>4,"02","01")) -> 01 | N8: =_xlfn.IFNA(VLOOKUP(RigheOfferte[[#This Row],[Lavorazione]],DescLavorazioni[],2,FALSE),"") | P8: =_xlfn.IFNA(VLOOKUP(RigheOfferte[[#This Row],[Cod Vel]],VeloCatena[],3,FALSE),0) -> 0 | V8: =IF(RigheOfferte[[#This Row],[Velocità]]>0,60*RigheOfferte[[#This Row],[Velocità]]/RigheOfferte[[#This Row],[passo]]*RigheOfferte[[#This Row],[nr.pezzi Telaio]],0) -> 0 | X8: =IFERROR(IF(OR(RigheOfferte[[#This Row],[Lavorazione]]="L1",RigheOfferte[[#This Row],[Lavorazione]]="L2",RigheOfferte[[#This Row],[Lavorazione]]="L3"),RigheOfferte[[#This Row],[Q.ta'']]/RigheOfferte[[#This Row],[nr.pezzi ora-unita]],RigheOfferte[[#This Row],[Q.ta'']]/RigheOfferte[[#This Row],[Pz Ora Altre Lav]]),0) -> 0 | Y8: =IFERROR(IF(OR(RigheOfferte[[#This Row],[Lavorazione]]="L1",RigheOfferte[[#This Row],[Lavorazione]]="L2",RigheOfferte[[#This Row],[Lavorazione]]="L3"),VLOOKUP(RigheOfferte[[#This Row],[lotto]],Lotti[],2,FALSE),0),0) -> 0 | Z8: =_xlfn.IFNA(INDEX(RiepilogoCostiOrari[],MATCH(YEAR(RigheOfferte[[#This Row],[data]])&RigheOfferte[[#This Row],[Quadrimestre]],QuCostiLav,0),MATCH(RigheOfferte[[#This Row],[Lavorazione]],CodLavorazioni,0)),0) -> 0 | AC8: =RigheOfferte[[#This Row],[Superf.pz Mq]]*Resa*RigheOfferte[[#This Row],[MP (€kg)]] -> 0 | AF8: =_xlfn.IFNA(VLOOKUP(RigheOfferte[[#This Row],[Tipo Protezione]],Protezioni[],2,FALSE),0) -> 0 | AH8: =IFERROR((RigheOfferte[[#This Row],[ORE LAVOR]]*RigheOfferte[[#This Row],[costo orario]]/RigheOfferte[[#This Row],[Q.ta'']])+(RigheOfferte[[#This Row],[cambio colore su pezzo]]/RigheOfferte[[#This Row],[Q.ta'']])+(RigheOfferte[[#This Row],[QtaProtez]]*RigheOfferte[[#This Row],[Costo Prot]])+RigheOfferte[[#This Row],[tot.CMP pz]],0) -> 0 | AI8: =RigheOfferte[[#This Row],[altri costi]]+RigheOfferte[[#This Row],[costo industriale pz]] -> 0 | AJ8: =_xlfn.IFNA(INDEX(Ricarichi[],MATCH(YEAR(RigheOfferte[[#This Row],[data]])&RigheOfferte[[#This Row],[Quadrimestre]],QuCostiLav,0),MATCH(RigheOfferte[[#This Row],[Lavorazione]],CodLavorazioni,0)),0) -> 0 | AK8: =RigheOfferte[[#This Row],[totale costi]]+(RigheOfferte[[#This Row],[totale costi]]*RigheOfferte[[#This Row],[Ricarico]]) -> 0 | AL8: =RigheOfferte[[#This Row],[Prezzo Di Vendita]]*RigheOfferte[[#This Row],[Q.ta'']] -> 0 | AM8: =IFERROR(RigheOfferte[[#This Row],[Prezzo Di Vendita]]/RigheOfferte[[#This Row],[Superf.pz Mq]],0) -> 0
A9: =IF(LEN('riepilogo prezzi'!$D9&'riepilogo prezzi'!$E9)>0,'riepilogo prezzi'!$D9&"-"&'riepilogo prezzi'!$E9,"") | B9: =IF(LEN(MONTH(RigheOfferte[[#This Row],[data]]))=1,0&MONTH(RigheOfferte[[#This Row],[data]]),MONTH(RigheOfferte[[#This Row],[data]])) -> 01 | C9: =IF(MONTH(RigheOfferte[[#This Row],[data]])>8,"03",IF(MONTH(RigheOfferte[[#This Row],[data]])>4,"02","01")) -> 01 | N9: =_xlfn.IFNA(VLOOKUP(RigheOfferte[[#This Row],[Lavorazione]],DescLavorazioni[],2,FALSE),"") | P9: =_xlfn.IFNA(VLOOKUP(RigheOfferte[[#This Row],[Cod Vel]],VeloCatena[],3,FALSE),0) -> 0 | V9: =IF(RigheOfferte[[#This Row],[Velocità]]>0,60*RigheOfferte[[#This Row],[Velocità]]/RigheOfferte[[#This Row],[passo]]*RigheOfferte[[#This Row],[nr.pezzi Telaio]],0) -> 0 | X9: =IFERROR(IF(OR(RigheOfferte[[#This Row],[Lavorazione]]="L1",RigheOfferte[[#This Row],[Lavorazione]]="L2",RigheOfferte[[#This Row],[Lavorazione]]="L3"),RigheOfferte[[#This Row],[Q.ta'']]/RigheOfferte[[#This Row],[nr.pezzi ora-unita]],RigheOfferte[[#This Row],[Q.ta'']]/RigheOfferte[[#This Row],[Pz Ora Altre Lav]]),0) -> 0 | Y9: =IFERROR(IF(OR(RigheOfferte[[#This Row],[Lavorazione]]="L1",RigheOfferte[[#This Row],[Lavorazione]]="L2",RigheOfferte[[#This Row],[Lavorazione]]="L3"),VLOOKUP(RigheOfferte[[#This Row],[lotto]],Lotti[],2,FALSE),0),0) -> 0 | Z9: =_xlfn.IFNA(INDEX(RiepilogoCostiOrari[],MATCH(YEAR(RigheOfferte[[#This Row],[data]])&RigheOfferte[[#This Row],[Quadrimestre]],QuCostiLav,0),MATCH(RigheOfferte[[#This Row],[Lavorazione]],CodLavorazioni,0)),0) -> 0 | AC9: =RigheOfferte[[#This Row],[Superf.pz Mq]]*Resa*RigheOfferte[[#This Row],[MP (€kg)]] -> 0 | AF9: =_xlfn.IFNA(VLOOKUP(RigheOfferte[[#This Row],[Tipo Protezione]],Protezioni[],2,FALSE),0) -> 0 | AH9: =IFERROR((RigheOfferte[[#This Row],[ORE LAVOR]]*RigheOfferte[[#This Row],[costo orario]]/RigheOfferte[[#This Row],[Q.ta'']])+(RigheOfferte[[#This Row],[cambio colore su pezzo]]/RigheOfferte[[#This Row],[Q.ta'']])+(RigheOfferte[[#This Row],[QtaProtez]]*RigheOfferte[[#This Row],[Costo Prot]])+RigheOfferte[[#This Row],[tot.CMP pz]],0) -> 0 | AI9: =RigheOfferte[[#This Row],[altri costi]]+RigheOfferte[[#This Row],[costo industriale pz]] -> 0 | AJ9: =_xlfn.IFNA(INDEX(Ricarichi[],MATCH(YEAR(RigheOfferte[[#This Row],[data]])&RigheOfferte[[#This Row],[Quadrimestre]],QuCostiLav,0),MATCH(RigheOfferte[[#This Row],[Lavorazione]],CodLavorazioni,0)),0) -> 0 | AK9: =RigheOfferte[[#This Row],[totale costi]]+(RigheOfferte[[#This Row],[totale costi]]*RigheOfferte[[#This Row],[Ricarico]]) -> 0 | AL9: =RigheOfferte[[#This Row],[Prezzo Di Vendita]]*RigheOfferte[[#This Row],[Q.ta'']] -> 0 | AM9: =IFERROR(RigheOfferte[[#This Row],[Prezzo Di Vendita]]/RigheOfferte[[#This Row],[Superf.pz Mq]],0) -> 0
A10: =IF(LEN('riepilogo prezzi'!$D10&'riepilogo prezzi'!$E10)>0,'riepilogo prezzi'!$D10&"-"&'riepilogo prezzi'!$E10,"") | B10: =IF(LEN(MONTH(RigheOfferte[[#This Row],[data]]))=1,0&MONTH(RigheOfferte[[#This Row],[data]]),MONTH(RigheOfferte[[#This Row],[data]])) -> 01 | C10: =IF(MONTH(RigheOfferte[[#This Row],[data]])>8,"03",IF(MONTH(RigheOfferte[[#This Row],[data]])>4,"02","01")) -> 01 | N10: =_xlfn.IFNA(VLOOKUP(RigheOfferte[[#This Row],[Lavorazione]],DescLavorazioni[],2,FALSE),"") | P10: =_xlfn.IFNA(VLOOKUP(RigheOfferte[[#This Row],[Cod Vel]],VeloCatena[],3,FALSE),0) -> 0 | V10: =IF(RigheOfferte[[#This Row],[Velocità]]>0,60*RigheOfferte[[#This Row],[Velocità]]/RigheOfferte[[#This Row],[passo]]*RigheOfferte[[#This Row],[nr.pezzi Telaio]],0) -> 0 | X10: =IFERROR(IF(OR(RigheOfferte[[#This Row],[Lavorazione]]="L1",RigheOfferte[[#This Row],[Lavorazione]]="L2",RigheOfferte[[#This Row],[Lavorazione]]="L3"),RigheOfferte[[#This Row],[Q.ta'']]/RigheOfferte[[#This Row],[nr.pezzi ora-unita]],RigheOfferte[[#This Row],[Q.ta'']]/RigheOfferte[[#This Row],[Pz Ora Altre Lav]]),0) -> 0 | Y10: =IFERROR(IF(OR(RigheOfferte[[#This Row],[Lavorazione]]="L1",RigheOfferte[[#This Row],[Lavorazione]]="L2",RigheOfferte[[#This Row],[Lavorazione]]="L3"),VLOOKUP(RigheOfferte[[#This Row],[lotto]],Lotti[],2,FALSE),0),0) -> 0 | Z10: =_xlfn.IFNA(INDEX(RiepilogoCostiOrari[],MATCH(YEAR(RigheOfferte[[#This Row],[data]])&RigheOfferte[[#This Row],[Quadrimestre]],QuCostiLav,0),MATCH(RigheOfferte[[#This Row],[Lavorazione]],CodLavorazioni,0)),0) -> 0 | AC10: =RigheOfferte[[#This Row],[Superf.pz Mq]]*Resa*RigheOfferte[[#This Row],[MP (€kg)]] -> 0 | AF10: =_xlfn.IFNA(VLOOKUP(RigheOfferte[[#This Row],[Tipo Protezione]],Protezioni[],2,FALSE),0) -> 0 | AH10: =IFERROR((RigheOfferte[[#This Row],[ORE LAVOR]]*RigheOfferte[[#This Row],[costo orario]]/RigheOfferte[[#This Row],[Q.ta'']])+(RigheOfferte[[#This Row],[cambio colore su pezzo]]/RigheOfferte[[#This Row],[Q.ta'']])+(RigheOfferte[[#This Row],[QtaProtez]]*RigheOfferte[[#This Row],[Costo Prot]])+RigheOfferte[[#This Row],[tot.CMP pz]],0) -> 0 | AI10: =RigheOfferte[[#This Row],[altri costi]]+RigheOfferte[[#This Row],[costo industriale pz]] -> 0 | AJ10: =_xlfn.IFNA(INDEX(Ricarichi[],MATCH(YEAR(RigheOfferte[[#This Row],[data]])&RigheOfferte[[#This Row],[Quadrimestre]],QuCostiLav,0),MATCH(RigheOfferte[[#This Row],[Lavorazione]],CodLavorazioni,0)),0) -> 0 | AK10: =RigheOfferte[[#This Row],[totale costi]]+(RigheOfferte[[#This Row],[totale costi]]*RigheOfferte[[#This Row],[Ricarico]]) -> 0 | AL10: =RigheOfferte[[#This Row],[Prezzo Di Vendita]]*RigheOfferte[[#This Row],[Q.ta'']] -> 0 | AM10: =IFERROR(RigheOfferte[[#This Row],[Prezzo Di Vendita]]/RigheOfferte[[#This Row],[Superf.pz Mq]],0) -> 0
A11: =IF(LEN('riepilogo prezzi'!$D11&'riepilogo prezzi'!$E11)>0,'riepilogo prezzi'!$D11&"-"&'riepilogo prezzi'!$E11,"") | B11: =IF(LEN(MONTH(RigheOfferte[[#This Row],[data]]))=1,0&MONTH(RigheOfferte[[#This Row],[data]]),MONTH(RigheOfferte[[#This Row],[data]])) -> 01 | C11: =IF(MONTH(RigheOfferte[[#This Row],[data]])>8,"03",IF(MONTH(RigheOfferte[[#This Row],[data]])>4,"02","01")) -> 01 | N11: =_xlfn.IFNA(VLOOKUP(RigheOfferte[[#This Row],[Lavorazione]],DescLavorazioni[],2,FALSE),"") | P11: =_xlfn.IFNA(VLOOKUP(RigheOfferte[[#This Row],[Cod Vel]],VeloCatena[],3,FALSE),0) -> 0 | V11: =IF(RigheOfferte[[#This Row],[Velocità]]>0,60*RigheOfferte[[#This Row],[Velocità]]/RigheOfferte[[#This Row],[passo]]*RigheOfferte[[#This Row],[nr.pezzi Telaio]],0) -> 0 | X11: =IFERROR(IF(OR(RigheOfferte[[#This Row],[Lavorazione]]="L1",RigheOfferte[[#This Row],[Lavorazione]]="L2",RigheOfferte[[#This Row],[Lavorazione]]="L3"),RigheOfferte[[#This Row],[Q.ta'']]/RigheOfferte[[#This Row],[nr.pezzi ora-unita]],RigheOfferte[[#This Row],[Q.ta'']]/RigheOfferte[[#This Row],[Pz Ora Altre Lav]]),0) -> 0 | Y11: =IFERROR(IF(OR(RigheOfferte[[#This Row],[Lavorazione]]="L1",RigheOfferte[[#This Row],[Lavorazione]]="L2",RigheOfferte[[#This Row],[Lavorazione]]="L3"),VLOOKUP(RigheOfferte[[#This Row],[lotto]],Lotti[],2,FALSE),0),0) -> 0 | Z11: =_xlfn.IFNA(INDEX(RiepilogoCostiOrari[],MATCH(YEAR(RigheOfferte[[#This Row],[data]])&RigheOfferte[[#This Row],[Quadrimestre]],QuCostiLav,0),MATCH(RigheOfferte[[#This Row],[Lavorazione]],CodLavorazioni,0)),0) -> 0 | AC11: =RigheOfferte[[#This Row],[Superf.pz Mq]]*Resa*RigheOfferte[[#This Row],[MP (€kg)]] -> 0 | AF11: =_xlfn.IFNA(VLOOKUP(RigheOfferte[[#This Row],[Tipo Protezione]],Protezioni[],2,FALSE),0) -> 0 | AH11: =IFERROR((RigheOfferte[[#This Row],[ORE LAVOR]]*RigheOfferte[[#This Row],[costo orario]]/RigheOfferte[[#This Row],[Q.ta'']])+(RigheOfferte[[#This Row],[cambio colore su pezzo]]/RigheOfferte[[#This Row],[Q.ta'']])+(RigheOfferte[[#This Row],[QtaProtez]]*RigheOfferte[[#This Row],[Costo Prot]])+RigheOfferte[[#This Row],[tot.CMP pz]],0) -> 0 | AI11: =RigheOfferte[[#This Row],[altri costi]]+RigheOfferte[[#This Row],[costo industriale pz]] -> 0 | AJ11: =_xlfn.IFNA(INDEX(Ricarichi[],MATCH(YEAR(RigheOfferte[[#This Row],[data]])&RigheOfferte[[#This Row],[Quadrimestre]],QuCostiLav,0),MATCH(RigheOfferte[[#This Row],[Lavorazione]],CodLavorazioni,0)),0) -> 0 | AK11: =RigheOfferte[[#This Row],[totale costi]]+(RigheOfferte[[#This Row],[totale costi]]*RigheOfferte[[#This Row],[Ricarico]]) -> 0 | AL11: =RigheOfferte[[#This Row],[Prezzo Di Vendita]]*RigheOfferte[[#This Row],[Q.ta'']] -> 0 | AM11: =IFERROR(RigheOfferte[[#This Row],[Prezzo Di Vendita]]/RigheOfferte[[#This Row],[Superf.pz Mq]],0) -> 0
A12: =IF(LEN('riepilogo prezzi'!$D12&'riepilogo prezzi'!$E12)>0,'riepilogo prezzi'!$D12&"-"&'riepilogo prezzi'!$E12,"") | B12: =IF(LEN(MONTH(RigheOfferte[[#This Row],[data]]))=1,0&MONTH(RigheOfferte[[#This Row],[data]]),MONTH(RigheOfferte[[#This Row],[data]])) -> 01 | C12: =IF(MONTH(RigheOfferte[[#This Row],[data]])>8,"03",IF(MONTH(RigheOfferte[[#This Row],[data]])>4,"02","01")) -> 01 | N12: =_xlfn.IFNA(VLOOKUP(RigheOfferte[[#This Row],[Lavorazione]],DescLavorazioni[],2,FALSE),"") | P12: =_xlfn.IFNA(VLOOKUP(RigheOfferte[[#This Row],[Cod Vel]],VeloCatena[],3,FALSE),0) -> 0 | V12: =IF(RigheOfferte[[#This Row],[Velocità]]>0,60*RigheOfferte[[#This Row],[Velocità]]/RigheOfferte[[#This Row],[passo]]*RigheOfferte[[#This Row],[nr.pezzi Telaio]],0) -> 0 | X12: =IFERROR(IF(OR(RigheOfferte[[#This Row],[Lavorazione]]="L1",RigheOfferte[[#This Row],[Lavorazione]]="L2",RigheOfferte[[#This Row],[Lavorazione]]="L3"),RigheOfferte[[#This Row],[Q.ta'']]/RigheOfferte[[#This Row],[nr.pezzi ora-unita]],RigheOfferte[[#This Row],[Q.ta'']]/RigheOfferte[[#This Row],[Pz Ora Altre Lav]]),0) -> 0 | Y12: =IFERROR(IF(OR(RigheOfferte[[#This Row],[Lavorazione]]="L1",RigheOfferte[[#This Row],[Lavorazione]]="L2",RigheOfferte[[#This Row],[Lavorazione]]="L3"),VLOOKUP(RigheOfferte[[#This Row],[lotto]],Lotti[],2,FALSE),0),0) -> 0 | Z12: =_xlfn.IFNA(INDEX(RiepilogoCostiOrari[],MATCH(YEAR(RigheOfferte[[#This Row],[data]])&RigheOfferte[[#This Row],[Quadrimestre]],QuCostiLav,0),MATCH(RigheOfferte[[#This Row],[Lavorazione]],CodLavorazioni,0)),0) -> 0 | AC12: =RigheOfferte[[#This Row],[Superf.pz Mq]]*Resa*RigheOfferte[[#This Row],[MP (€kg)]] -> 0 | AF12: =_xlfn.IFNA(VLOOKUP(RigheOfferte[[#This Row],[Tipo Protezione]],Protezioni[],2,FALSE),0) -> 0 | AH12: =IFERROR((RigheOfferte[[#This Row],[ORE LAVOR]]*RigheOfferte[[#This Row],[costo orario]]/RigheOfferte[[#This Row],[Q.ta'']])+(RigheOfferte[[#This Row],[cambio colore su pezzo]]/RigheOfferte[[#This Row],[Q.ta'']])+(RigheOfferte[[#This Row],[QtaProtez]]*RigheOfferte[[#This Row],[Costo Prot]])+RigheOfferte[[#This Row],[tot.CMP pz]],0) -> 0 | AI12: =RigheOfferte[[#This Row],[altri costi]]+RigheOfferte[[#This Row],[costo industriale pz]] -> 0 | AJ12: =_xlfn.IFNA(INDEX(Ricarichi[],MATCH(YEAR(RigheOfferte[[#This Row],[data]])&RigheOfferte[[#This Row],[Quadrimestre]],QuCostiLav,0),MATCH(RigheOfferte[[#This Row],[Lavorazione]],CodLavorazioni,0)),0) -> 0 | AK12: =RigheOfferte[[#This Row],[totale costi]]+(RigheOfferte[[#This Row],[totale costi]]*RigheOfferte[[#This Row],[Ricarico]]) -> 0 | AL12: =RigheOfferte[[#This Row],[Prezzo Di Vendita]]*RigheOfferte[[#This Row],[Q.ta'']] -> 0 | AM12: =IFERROR(RigheOfferte[[#This Row],[Prezzo Di Vendita]]/RigheOfferte[[#This Row],[Superf.pz Mq]],0) -> 0
A13: =IF(LEN('riepilogo prezzi'!$D13&'riepilogo prezzi'!$E13)>0,'riepilogo prezzi'!$D13&"-"&'riepilogo prezzi'!$E13,"") | B13: =IF(LEN(MONTH(RigheOfferte[[#This Row],[data]]))=1,0&MONTH(RigheOfferte[[#This Row],[data]]),MONTH(RigheOfferte[[#This Row],[data]])) -> 01 | C13: =IF(MONTH(RigheOfferte[[#This Row],[data]])>8,"03",IF(MONTH(RigheOfferte[[#This Row],[data]])>4,"02","01")) -> 01 | N13: =_xlfn.IFNA(VLOOKUP(RigheOfferte[[#This Row],[Lavorazione]],DescLavorazioni[],2,FALSE),"") | P13: =_xlfn.IFNA(VLOOKUP(RigheOfferte[[#This Row],[Cod Vel]],VeloCatena[],3,FALSE),0) -> 0 | V13: =IF(RigheOfferte[[#This Row],[Velocità]]>0,60*RigheOfferte[[#This Row],[Velocità]]/RigheOfferte[[#This Row],[passo]]*RigheOfferte[[#This Row],[nr.pezzi Telaio]],0) -> 0 | X13: =IFERROR(IF(OR(RigheOfferte[[#This Row],[Lavorazione]]="L1",RigheOfferte[[#This Row],[Lavorazione]]="L2",RigheOfferte[[#This Row],[Lavorazione]]="L3"),RigheOfferte[[#This Row],[Q.ta'']]/RigheOfferte[[#This Row],[nr.pezzi ora-unita]],RigheOfferte[[#This Row],[Q.ta'']]/RigheOfferte[[#This Row],[Pz Ora Altre Lav]]),0) -> 0 | Y13: =IFERROR(IF(OR(RigheOfferte[[#This Row],[Lavorazione]]="L1",RigheOfferte[[#This Row],[Lavorazione]]="L2",RigheOfferte[[#This Row],[Lavorazione]]="L3"),VLOOKUP(RigheOfferte[[#This Row],[lotto]],Lotti[],2,FALSE),0),0) -> 0 | Z13: =_xlfn.IFNA(INDEX(RiepilogoCostiOrari[],MATCH(YEAR(RigheOfferte[[#This Row],[data]])&RigheOfferte[[#This Row],[Quadrimestre]],QuCostiLav,0),MATCH(RigheOfferte[[#This Row],[Lavorazione]],CodLavorazioni,0)),0) -> 0 | AC13: =RigheOfferte[[#This Row],[Superf.pz Mq]]*Resa*RigheOfferte[[#This Row],[MP (€kg)]] -> 0 | AF13: =_xlfn.IFNA(VLOOKUP(RigheOfferte[[#This Row],[Tipo Protezione]],Protezioni[],2,FALSE),0) -> 0 | AH13: =IFERROR((RigheOfferte[[#This Row],[ORE LAVOR]]*RigheOfferte[[#This Row],[costo orario]]/RigheOfferte[[#This Row],[Q.ta'']])+(RigheOfferte[[#This Row],[cambio colore su pezzo]]/RigheOfferte[[#This Row],[Q.ta'']])+(RigheOfferte[[#This Row],[QtaProtez]]*RigheOfferte[[#This Row],[Costo Prot]])+RigheOfferte[[#This Row],[tot.CMP pz]],0) -> 0 | AI13: =RigheOfferte[[#This Row],[altri costi]]+RigheOfferte[[#This Row],[costo industriale pz]] -> 0 | AJ13: =_xlfn.IFNA(INDEX(Ricarichi[],MATCH(YEAR(RigheOfferte[[#This Row],[data]])&RigheOfferte[[#This Row],[Quadrimestre]],QuCostiLav,0),MATCH(RigheOfferte[[#This Row],[Lavorazione]],CodLavorazioni,0)),0) -> 0 | AK13: =RigheOfferte[[#This Row],[totale costi]]+(RigheOfferte[[#This Row],[totale costi]]*RigheOfferte[[#This Row],[Ricarico]]) -> 0 | AL13: =RigheOfferte[[#This Row],[Prezzo Di Vendita]]*RigheOfferte[[#This Row],[Q.ta'']] -> 0 | AM13: =IFERROR(RigheOfferte[[#This Row],[Prezzo Di Vendita]]/RigheOfferte[[#This Row],[Superf.pz Mq]],0) -> 0
A14: =IF(LEN('riepilogo prezzi'!$D14&'riepilogo prezzi'!$E14)>0,'riepilogo prezzi'!$D14&"-"&'riepilogo prezzi'!$E14,"") | B14: =IF(LEN(MONTH(RigheOfferte[[#This Row],[data]]))=1,0&MONTH(RigheOfferte[[#This Row],[data]]),MONTH(RigheOfferte[[#This Row],[data]])) -> 01 | C14: =IF(MONTH(RigheOfferte[[#This Row],[data]])>8,"03",IF(MONTH(RigheOfferte[[#This Row],[data]])>4,"02","01")) -> 01 | N14: =_xlfn.IFNA(VLOOKUP(RigheOfferte[[#This Row],[Lavorazione]],DescLavorazioni[],2,FALSE),"") | P14: =_xlfn.IFNA(VLOOKUP(RigheOfferte[[#This Row],[Cod Vel]],VeloCatena[],3,FALSE),0) -> 0 | V14: =IF(RigheOfferte[[#This Row],[Velocità]]>0,60*RigheOfferte[[#This Row],[Velocità]]/RigheOfferte[[#This Row],[passo]]*RigheOfferte[[#This Row],[nr.pezzi Telaio]],0) -> 0 | X14: =IFERROR(IF(OR(RigheOfferte[[#This Row],[Lavorazione]]="L1",RigheOfferte[[#This Row],[Lavorazione]]="L2",RigheOfferte[[#This Row],[Lavorazione]]="L3"),RigheOfferte[[#This Row],[Q.ta'']]/RigheOfferte[[#This Row],[nr.pezzi ora-unita]],RigheOfferte[[#This Row],[Q.ta'']]/RigheOfferte[[#This Row],[Pz Ora Altre Lav]]),0) -> 0 | Y14: =IFERROR(IF(OR(RigheOfferte[[#This Row],[Lavorazione]]="L1",RigheOfferte[[#This Row],[Lavorazione]]="L2",RigheOfferte[[#This Row],[Lavorazione]]="L3"),VLOOKUP(RigheOfferte[[#This Row],[lotto]],Lotti[],2,FALSE),0),0) -> 0 | Z14: =_xlfn.IFNA(INDEX(RiepilogoCostiOrari[],MATCH(YEAR(RigheOfferte[[#This Row],[data]])&RigheOfferte[[#This Row],[Quadrimestre]],QuCostiLav,0),MATCH(RigheOfferte[[#This Row],[Lavorazione]],CodLavorazioni,0)),0) -> 0 | AC14: =RigheOfferte[[#This Row],[Superf.pz Mq]]*Resa*RigheOfferte[[#This Row],[MP (€kg)]] -> 0 | AF14: =_xlfn.IFNA(VLOOKUP(RigheOfferte[[#This Row],[Tipo Protezione]],Protezioni[],2,FALSE),0) -> 0 | AH14: =IFERROR((RigheOfferte[[#This Row],[ORE LAVOR]]*RigheOfferte[[#This Row],[costo orario]]/RigheOfferte[[#This Row],[Q.ta'']])+(RigheOfferte[[#This Row],[cambio colore su pezzo]]/RigheOfferte[[#This Row],[Q.ta'']])+(RigheOfferte[[#This Row],[QtaProtez]]*RigheOfferte[[#This Row],[Costo Prot]])+RigheOfferte[[#This Row],[tot.CMP pz]],0) -> 0 | AI14: =RigheOfferte[[#This Row],[altri costi]]+RigheOfferte[[#This Row],[costo industriale pz]] -> 0 | AJ14: =_xlfn.IFNA(INDEX(Ricarichi[],MATCH(YEAR(RigheOfferte[[#This Row],[data]])&RigheOfferte[[#This Row],[Quadrimestre]],QuCostiLav,0),MATCH(RigheOfferte[[#This Row],[Lavorazione]],CodLavorazioni,0)),0) -> 0 | AK14: =RigheOfferte[[#This Row],[totale costi]]+(RigheOfferte[[#This Row],[totale costi]]*RigheOfferte[[#This Row],[Ricarico]]) -> 0 | AL14: =RigheOfferte[[#This Row],[Prezzo Di Vendita]]*RigheOfferte[[#This Row],[Q.ta'']] -> 0 | AM14: =IFERROR(RigheOfferte[[#This Row],[Prezzo Di Vendita]]/RigheOfferte[[#This Row],[Superf.pz Mq]],0) -> 0
A15: =IF(LEN('riepilogo prezzi'!$D15&'riepilogo prezzi'!$E15)>0,'riepilogo prezzi'!$D15&"-"&'riepilogo prezzi'!$E15,"") | B15: =IF(LEN(MONTH(RigheOfferte[[#This Row],[data]]))=1,0&MONTH(RigheOfferte[[#This Row],[data]]),MONTH(RigheOfferte[[#This Row],[data]])) -> 01 | C15: =IF(MONTH(RigheOfferte[[#This Row],[data]])>8,"03",IF(MONTH(RigheOfferte[[#This Row],[data]])>4,"02","01")) -> 01 | N15: =_xlfn.IFNA(VLOOKUP(RigheOfferte[[#This Row],[Lavorazione]],DescLavorazioni[],2,FALSE),"") | P15: =_xlfn.IFNA(VLOOKUP(RigheOfferte[[#This Row],[Cod Vel]],VeloCatena[],3,FALSE),0) -> 0 | V15: =IF(RigheOfferte[[#This Row],[Velocità]]>0,60*RigheOfferte[[#This Row],[Velocità]]/RigheOfferte[[#This Row],[passo]]*RigheOfferte[[#This Row],[nr.pezzi Telaio]],0) -> 0 | X15: =IFERROR(IF(OR(RigheOfferte[[#This Row],[Lavorazione]]="L1",RigheOfferte[[#This Row],[Lavorazione]]="L2",RigheOfferte[[#This Row],[Lavorazione]]="L3"),RigheOfferte[[#This Row],[Q.ta'']]/RigheOfferte[[#This Row],[nr.pezzi ora-unita]],RigheOfferte[[#This Row],[Q.ta'']]/RigheOfferte[[#This Row],[Pz Ora Altre Lav]]),0) -> 0 | Y15: =IFERROR(IF(OR(RigheOfferte[[#This Row],[Lavorazione]]="L1",RigheOfferte[[#This Row],[Lavorazione]]="L2",RigheOfferte[[#This Row],[Lavorazione]]="L3"),VLOOKUP(RigheOfferte[[#This Row],[lotto]],Lotti[],2,FALSE),0),0) -> 0 | Z15: =_xlfn.IFNA(INDEX(RiepilogoCostiOrari[],MATCH(YEAR(RigheOfferte[[#This Row],[data]])&RigheOfferte[[#This Row],[Quadrimestre]],QuCostiLav,0),MATCH(RigheOfferte[[#This Row],[Lavorazione]],CodLavorazioni,0)),0) -> 0 | AC15: =RigheOfferte[[#This Row],[Superf.pz Mq]]*Resa*RigheOfferte[[#This Row],[MP (€kg)]] -> 0 | AF15: =_xlfn.IFNA(VLOOKUP(RigheOfferte[[#This Row],[Tipo Protezione]],Protezioni[],2,FALSE),0) -> 0 | AH15: =IFERROR((RigheOfferte[[#This Row],[ORE LAVOR]]*RigheOfferte[[#This Row],[costo orario]]/RigheOfferte[[#This Row],[Q.ta'']])+(RigheOfferte[[#This Row],[cambio colore su pezzo]]/RigheOfferte[[#This Row],[Q.ta'']])+(RigheOfferte[[#This Row],[QtaProtez]]*RigheOfferte[[#This Row],[Costo Prot]])+RigheOfferte[[#This Row],[tot.CMP pz]],0) -> 0 | AI15: =RigheOfferte[[#This Row],[altri costi]]+RigheOfferte[[#This Row],[costo industriale pz]] -> 0 | AJ15: =_xlfn.IFNA(INDEX(Ricarichi[],MATCH(YEAR(RigheOfferte[[#This Row],[data]])&RigheOfferte[[#This Row],[Quadrimestre]],QuCostiLav,0),MATCH(RigheOfferte[[#This Row],[Lavorazione]],CodLavorazioni,0)),0) -> 0 | AK15: =RigheOfferte[[#This Row],[totale costi]]+(RigheOfferte[[#This Row],[totale costi]]*RigheOfferte[[#This Row],[Ricarico]]) -> 0 | AL15: =RigheOfferte[[#This Row],[Prezzo Di Vendita]]*RigheOfferte[[#This Row],[Q.ta'']] -> 0 | AM15: =IFERROR(RigheOfferte[[#This Row],[Prezzo Di Vendita]]/RigheOfferte[[#This Row],[Superf.pz Mq]],0) -> 0
